{"pred_running": false, "error": "Unhandled exception: Traceback (most recent call last):\n  File \"C:\\Ampps\\www\\AIFCOMSSwithCUPredictorTest\\predict.py\", line 711, in <module>\n    main()\n  File \"C:\\Python27\\lib\\site-packages\\statsd.py\", line 144, in f\n    return func(*args, **kw)\n  File \"C:\\Ampps\\www\\AIFCOMSSwithCUPredictorTest\\predict.py\", line 267, in main\n    dataset_times = map(timestamp_to_datetime, dataset.time)\nTypeError: argument 2 to map() must support iteration\n", "run_time": "1525286277", "gfs_timestamp": "gfs20180502_1p00", "warnings": false, "pred_complete": false, "pred_output": [], "gfs_percent": 0, "gfs_complete": false, "gfs_timeremaining": "Please wait..."}