{"pred_running": false, "error": "Unhandled exception: Traceback (most recent call last):\n  File \"C:\\Ampps\\www\\AIFCOMSSwithCUPredictorTest\\predict.py\", line 711, in <module>\n    main()\n  File \"C:\\Python27\\lib\\site-packages\\statsd.py\", line 144, in f\n    return func(*args, **kw)\n  File \"C:\\Ampps\\www\\AIFCOMSSwithCUPredictorTest\\predict.py\", line 296, in main\n    time_to_find + datetime.timedelta(hours=options.future))\n  File \"C:\\Ampps\\www\\AIFCOMSSwithCUPredictorTest\\predict.py\", line 400, in write_file\n    enumerate(hgtprs_global.maps['lon']))\n  File \"C:\\Python27\\lib\\site-packages\\pydap\\model.py\", line 212, in __iter__\n    def __iter__(self): return iter(self.data)\n  File \"C:\\Python27\\lib\\site-packages\\pydap\\proxy.py\", line 102, in __iter__\n    return iter(self[:])\n  File \"C:\\Python27\\lib\\site-packages\\pydap\\proxy.py\", line 112, in __getitem__\n    resp, data = request(url)\n  File \"C:\\Python27\\lib\\site-packages\\pydap\\util\\http.py\", line 50, in request\n    raise ServerError(msg)\nServerError: 'Server error 0: \"/gfs_1p00/gfs20180525/gfs_1p00_12z is not an available dataset\"'\n", "run_time": "1527268610", "gfs_timestamp": "gfs20180525_1p00", "warnings": false, "pred_complete": false, "pred_output": [], "gfs_percent": 0, "gfs_complete": false, "gfs_timeremaining": "Please wait..."}