{"pred_running": false, "error": "Unhandled exception: Traceback (most recent call last):\n  File \"C:\\Ampps\\www\\AIFCOMSSwithCUPredictorTest\\predict.py\", line 711, in <module>\n    main()\n  File \"C:\\Python27\\lib\\site-packages\\statsd.py\", line 144, in f\n    return func(*args, **kw)\n  File \"C:\\Ampps\\www\\AIFCOMSSwithCUPredictorTest\\predict.py\", line 276, in main\n    log.info('      Latitude: %s -> %s' % (min(dataset.lat), max(dataset.lat)))\n  File \"C:\\Python27\\lib\\site-packages\\pydap\\model.py\", line 212, in __iter__\n    def __iter__(self): return iter(self.data)\n  File \"C:\\Python27\\lib\\site-packages\\pydap\\proxy.py\", line 102, in __iter__\n    return iter(self[:])\n  File \"C:\\Python27\\lib\\site-packages\\pydap\\proxy.py\", line 112, in __getitem__\n    resp, data = request(url)\n  File \"C:\\Python27\\lib\\site-packages\\pydap\\util\\http.py\", line 50, in request\n    raise ServerError(msg)\nServerError: 'Server error 0: \"extraction failed; not enough lat data in /tomcat_cache/gds/grads/dods/gfs_1p00/gfs20180528/gfs_1p00_06z.lat.output\"'\n", "run_time": "1527526735", "gfs_timestamp": "gfs20180528_1p00", "warnings": false, "pred_complete": false, "pred_output": [], "gfs_percent": 0, "gfs_complete": false, "gfs_timeremaining": "Please wait..."}