{"pred_running": false, "error": "Unhandled exception: Traceback (most recent call last):\n  File \"C:\\Ampps\\www\\AIFCOMSSwithCUPredictorTest\\predict.py\", line 711, in <module>\n    main()\n  File \"C:\\Python27\\lib\\site-packages\\statsd.py\", line 144, in f\n    return func(*args, **kw)\n  File \"C:\\Ampps\\www\\AIFCOMSSwithCUPredictorTest\\predict.py\", line 296, in main\n    time_to_find + datetime.timedelta(hours=options.future))\n  File \"C:\\Ampps\\www\\AIFCOMSSwithCUPredictorTest\\predict.py\", line 450, in write_file\n    longitudes[0][0]:(longitudes[-1][0]+1) ]\n  File \"C:\\Python27\\lib\\site-packages\\pydap\\model.py\", line 628, in __getitem__\n    var.data = var.data[slice_]\n  File \"C:\\Python27\\lib\\site-packages\\pydap\\proxy.py\", line 112, in __getitem__\n    resp, data = request(url)\n  File \"C:\\Python27\\lib\\site-packages\\pydap\\util\\http.py\", line 50, in request\n    raise ServerError(msg)\nServerError: 'Server error 0: \"/gfs_1p00/gfs20180528/gfs_1p00_06z is not an available dataset\"'\n", "run_time": "1527531495", "gfs_timestamp": "gfs20180528_1p00", "warnings": false, "pred_complete": false, "pred_output": [], "gfs_percent": 30, "gfs_complete": false, "gfs_timeremaining": "00:00"}