{"pred_running": false, "error": "Unhandled exception: Traceback (most recent call last):\n  File \"C:\\Ampps\\www\\AIFCOMSSwithCUPredictorTest\\predict.py\", line 711, in <module>\n    main()\n  File \"C:\\Python27\\lib\\site-packages\\statsd.py\", line 144, in f\n    return func(*args, **kw)\n  File \"C:\\Ampps\\www\\AIFCOMSSwithCUPredictorTest\\predict.py\", line 288, in main\n    gfs_dir = tempfile.mkdtemp(dir=gfs_dir)\n  File \"C:\\Python27\\lib\\tempfile.py\", line 339, in mkdtemp\n    _os.mkdir(file, 0700)\nWindowsError: [Error 3] The system cannot find the path specified: '/path/to/AIFCOMSSwithCUPredictorTest\\\\gfs\\\\tmpoujyl5'\n", "run_time": "1525281219", "gfs_timestamp": "gfs20180502_1p00", "warnings": false, "pred_complete": false, "pred_output": [], "gfs_percent": 0, "gfs_complete": false, "gfs_timeremaining": "Please wait..."}