{"pred_running": false, "error": "Unhandled exception: Traceback (most recent call last):\n  File \"C:\\Ampps\\www\\AIFCOMSSwithCUPredictorTest\\predict.py\", line 711, in <module>\n    main()\n  File \"C:\\Python27\\lib\\site-packages\\statsd.py\", line 144, in f\n    return func(*args, **kw)\n  File \"C:\\Ampps\\www\\AIFCOMSSwithCUPredictorTest\\predict.py\", line 296, in main\n    time_to_find + datetime.timedelta(hours=options.future))\n  File \"C:\\Ampps\\www\\AIFCOMSSwithCUPredictorTest\\predict.py\", line 450, in write_file\n    longitudes[0][0]:(longitudes[-1][0]+1) ]\n  File \"C:\\Python27\\lib\\site-packages\\pydap\\model.py\", line 628, in __getitem__\n    var.data = var.data[slice_]\n  File \"C:\\Python27\\lib\\site-packages\\pydap\\proxy.py\", line 112, in __getitem__\n    resp, data = request(url)\n  File \"C:\\Python27\\lib\\site-packages\\pydap\\util\\http.py\", line 42, in request\n    'connection': 'close'})\n  File \"C:\\Python27\\lib\\site-packages\\httplib2\\__init__.py\", line 1694, in request\n    (response, content) = self._request(conn, authority, uri, request_uri, method, body, headers, redirections, cachekey)\n  File \"C:\\Python27\\lib\\site-packages\\httplib2\\__init__.py\", line 1434, in _request\n    (response, content) = self._conn_request(conn, request_uri, method, body, headers)\n  File \"C:\\Python27\\lib\\site-packages\\httplib2\\__init__.py\", line 1390, in _conn_request\n    response = conn.getresponse()\n  File \"C:\\Python27\\lib\\httplib.py\", line 1121, in getresponse\n    response.begin()\n  File \"C:\\Python27\\lib\\httplib.py\", line 438, in begin\n    version, status, reason = self._read_status()\n  File \"C:\\Python27\\lib\\httplib.py\", line 394, in _read_status\n    line = self.fp.readline(_MAXLINE + 1)\n  File \"C:\\Python27\\lib\\socket.py\", line 480, in readline\n    data = self._sock.recv(self._rbufsize)\nerror: [Errno 10060] A connection attempt failed because the connected party did not properly respond after a period of time, or established connection failed because connected host has failed to respond\n", "run_time": "1525287075", "gfs_timestamp": "gfs20180502_1p00", "warnings": false, "pred_complete": false, "pred_output": [], "gfs_percent": 40, "gfs_complete": false, "gfs_timeremaining": "00:00"}